<?xml version="1.0" ?>
<!-- =================================================================================== -->
<!-- |    This document was autogenerated by xacro from /home/industry4/slider_fanuc/src/robot_slider_description/urdf/fanuc_boat.urdf.xacro | -->
<!-- |    EDITING THIS FILE BY HAND IS NOT RECOMMENDED                                 | -->
<!-- =================================================================================== -->
<robot name="fanuc">
    <link name="world" />
    <link name="boat_link">
        <inertial>
            <origin rpy="0 0 0" xyz="0.0029912 -0.083551 0.56051" />
            <mass value="300.98" />
            <inertia ixx="65.942" ixy="-0.0012689" ixz="-0.044489" iyy="74.027" iyz="-0.19476" izz="15.95" />
        </inertial>
        <visual>
            <geometry>
                <mesh filename="package://robot_slider_description/meshes/boatwithstand.dae" scale="1 1 1" />
            </geometry>
        </visual>
        <collision>
            <origin rpy="0 1.57 0 " xyz="0 0.25 -12" />
            <geometry>
                <box size="30 0.5 0.3" />
            </geometry>
        </collision>
    </link>
    <link name="rail_stand_link_right">
        <inertial>
            <origin rpy="0 0 0" xyz="0.0029912 -0.083551 0.56051" />
            <mass value="300.98" />
            <inertia ixx="65.942" ixy="-0.0012689" ixz="-0.044489" iyy="74.027" iyz="-0.19476" izz="15.95" />
        </inertial>
        <visual>
            <geometry>
                <mesh filename="package://robot_slider_description/meshes/rail_stand.dae" scale="1 1 1" />
            </geometry>
        </visual>
        <collision>
            <origin rpy=" 0 1.57 0.0" xyz="0.7 0.125 -12" />
            <geometry>
                <box size="30 0.25 1.3" />
            </geometry>
        </collision>
    </link>
    <joint name="boat_world_joint" type="fixed">
        <parent link="world" />
        <child link="boat_link" />
        <origin rpy="1.57 0.0 0" xyz="0 0 0" />
    </joint>
    <joint name="rail_stand_right_world_joint" type="fixed">
        <parent link="world" />
        <child link="rail_stand_link_right" />
        <origin rpy="1.57 0.0 0" xyz="1.2 0 0" />
    </joint>
    <link name="slider_link">
        <inertial>
            <origin rpy="0 0 0" xyz="0.75 1.0487 -3.6486" />
            <mass value="1317.8" />
            <inertia ixx="353.39" ixy="3.9338E-12" ixz="3.5103E-13" iyy="420.06" iyz="4.9967E-13" izz="170.54" />
        </inertial>
        <visual>
            <origin rpy="0 0 0" xyz="0 0 0" />
            <geometry>
                <mesh filename="package://robot_slider_description/meshes/slider_link.STL" />
            </geometry>
            <material name="">
                <color rgba="0.019608 0.019608 0.019608 1" />
            </material>
        </visual>
        <collision>
            <origin rpy="0 0 0" xyz="0 0 0" />
            <geometry>
                <mesh filename="package://robot_slider_description/meshes/slider_link.STL" />
            </geometry>
        </collision>
    </link>
    <link name="robot_stand">
        <inertial>
            <origin rpy="0 0 0" xyz="0.0029912 -0.083551 0.56051" />
            <mass value="300.98" />
            <inertia ixx="65.942" ixy="-0.0012689" ixz="-0.044489" iyy="74.027" iyz="-0.19476" izz="15.95" />
        </inertial>
        <visual>
            <origin rpy="0 0 0" xyz="0 0 0" />
            <geometry>
                <mesh filename="package://robot_slider_description/meshes/robot_stand.STL" />
            </geometry>
            <material name="">
                <color rgba="0.99608 0.99608 1 1" />
            </material>
        </visual>
        <collision>
            <origin rpy="0 0 0" xyz="0 0 0" />
            <geometry>
                <mesh filename="package://robot_slider_description/meshes/robot_stand.STL" />
            </geometry>
        </collision>
    </link>
    <joint name="robot_stand_slider_joint" type="revolute">
        <origin rpy="-1.5708 0 -0.46063" xyz="0.75 3.6486 2.7" />
        <parent link="slider_link" />
        <child link="robot_stand" />
        <axis xyz="0 1 0" />
        <limit effort="1" lower="-0.7853981633974483" upper="3.141592653589793" velocity="1" />
    </joint>
    <joint name="slider_link_rail_stand_right_joint" type="prismatic">
        <parent link="rail_stand_link_right" />
        <child link="slider_link" />
        <origin rpy="-1.57 0.0 0" xyz="0 0 0" />
        <axis xyz="0.0 1 0.0" />
        <limit effort="3" lower="-1.8" upper="21" velocity="2" />
    </joint>
    <link name="base_link">
        <inertial>
            <mass value="1.584994" />
            <origin rpy="0 0 0" xyz="0.0 0.0 0.0" />
            <inertia ixx="0.01042" ixy="0.001177" ixz="-0.0008871" iyy="0.01045" iyz="0.0002226" izz="0.01817" />
        </inertial>
        <visual>
            <geometry>
                <mesh filename="package://robot_slider_description/meshes/base_link.stl" scale="1 1 1" />
            </geometry>
            <material name="RED">
                <color rgba="1.0 0.0 0.0 1.0" />
            </material>
        </visual>
        <collision>
            <geometry>
                <mesh filename="package://robot_slider_description/meshes/base_link.stl" scale="1 1 1" />
            </geometry>
        </collision>
    </link>
    <joint name="joint_1" type="revolute">
        <parent link="base_link" />
        <child link="link_1" />
        <origin rpy="0.0 0.0 0.0" xyz="0 0 0.670" />
        <axis xyz="0 0 1" />
        <limit effort="150.0" lower="-3.142" upper="3.142" velocity="1.5" />
    </joint>
    <link name="link_1">
        <inertial>
            <mass value="0.4" />
            <origin rpy="0 0 0" xyz="0.0 0.0 0.0" />
            <inertia ixx="0.01042" ixy="0.001177" ixz="-0.0008871" iyy="0.01045" iyz="0.0002226" izz="0.01817" />
        </inertial>
        <visual>
            <geometry>
                <mesh filename="package://robot_slider_description/meshes/link_1.stl" scale="1 1 1" />
            </geometry>
            <material name="voilet">
                <color rgba="1.0 0.3 1.0 1.0" />
            </material>
        </visual>
        <collision>
            <geometry>
                <mesh filename="package://robot_slider_description/meshes/link_1.stl" scale="1 1 1" />
            </geometry>
        </collision>
    </link>
    <joint name="joint_2" type="revolute">
        <parent link="link_1" />
        <child link="link_2" />
        <origin rpy="0.0 0.0 0.0" xyz="0.312 0 0" />
        <axis xyz="0 1 0" />
        <limit effort="150.0" lower="-1.0472" upper="1.3264" velocity="1.5" />
    </joint>
    <link name="link_2">
        <inertial>
            <mass value="0.4" />
            <origin rpy="0 0 0" xyz="0.0 0.0 0.0" />
            <inertia ixx="0.01042" ixy="0.001177" ixz="-0.0008871" iyy="0.01045" iyz="0.0002226" izz="0.01817" />
        </inertial>
        <visual>
            <geometry>
                <mesh filename="package://robot_slider_description/meshes/link_2.stl" scale="1 1 1" />
            </geometry>
            <material name="voilet">
                <color rgba="1.0 0.3 1.0 1.0" />
            </material>
        </visual>
        <collision>
            <geometry>
                <mesh filename="package://robot_slider_description/meshes/link_2.stl" scale="1 1 1" />
            </geometry>
        </collision>
    </link>
    <joint name="joint_3" type="revolute">
        <parent link="link_2" />
        <child link="link_3" />
        <origin rpy="0.0 0.0 0.0" xyz="0 0 1.075" />
        <axis xyz="0 -1 0" />
        <limit effort="150.0" lower="-2.303" upper="4.014" velocity="1.5" />
    </joint>
    <link name="link_3">
        <inertial>
            <mass value="0.4" />
            <origin rpy="0 0 0" xyz="0.0 0.0 0.0" />
            <inertia ixx="0.01042" ixy="0.001177" ixz="-0.0008871" iyy="0.01045" iyz="0.0002226" izz="0.01817" />
        </inertial>
        <visual>
            <geometry>
                <mesh filename="package://robot_slider_description/meshes/link_3.stl" scale="1 1 1" />
            </geometry>
            <material name="voilet">
                <color rgba="1.0 0.3 1.0 1.0" />
            </material>
        </visual>
        <collision>
            <geometry>
                <mesh filename="package://robot_slider_description/meshes/link_3.stl" scale="1 1 1" />
            </geometry>
        </collision>
    </link>
    <joint name="joint_4" type="revolute">
        <parent link="link_3" />
        <child link="link_4" />
        <origin rpy="0.0 0.0 0.0" xyz="0 0 0.225" />
        <axis xyz="-1 0 0" />
        <limit effort="150.0" lower="-6.28" upper="6.28" velocity="1.5" />
    </joint>
    <link name="link_4">
        <inertial>
            <mass value="0.4" />
            <origin rpy="0 0 0" xyz="0.0 0.0 0.0" />
            <inertia ixx="0.01042" ixy="0.001177" ixz="-0.0008871" iyy="0.01045" iyz="0.0002226" izz="0.01817" />
        </inertial>
        <visual>
            <geometry>
                <mesh filename="package://robot_slider_description/meshes/link_4.stl" scale="1 1 1" />
            </geometry>
            <material name="voilet">
                <color rgba="1.0 0.3 1.0 1.0" />
            </material>
        </visual>
        <collision>
            <geometry>
                <mesh filename="package://robot_slider_description/meshes/link_4.stl" scale="1 1 1" />
            </geometry>
        </collision>
    </link>
    <joint name="joint_5" type="revolute">
        <parent link="link_4" />
        <child link="link_5" />
        <origin rpy="0.0 0.0 0.0" xyz="1.280 0 0" />
        <axis xyz="0 -1 0" />
        <limit effort="150.0" lower="-2.181" upper="2.181" velocity="1.5" />
    </joint>
    <link name="link_5">
        <inertial>
            <mass value="0.4" />
            <origin rpy="0 0 0" xyz="0.0 0.0 0.0" />
            <inertia ixx="0.01042" ixy="0.001177" ixz="-0.0008871" iyy="0.01045" iyz="0.0002226" izz="0.01817" />
        </inertial>
        <visual>
            <geometry>
                <mesh filename="package://robot_slider_description/meshes/link_5.stl" scale="1 1 1" />
            </geometry>
            <material name="voilet">
                <color rgba="1.0 0.3 1.0 1.0" />
            </material>
        </visual>
        <collision>
            <geometry>
                <mesh filename="package://robot_slider_description/meshes/link_5.stl" scale="1 1 1" />
            </geometry>
        </collision>
    </link>
    <joint name="joint_6" type="revolute">
        <parent link="link_5" />
        <child link="link_6" />
        <origin rpy="0.0 0.0 0.0" xyz="0.235 0 0" />
        <axis xyz="-1 0 0" />
        <limit effort="150.0" lower="-6.28" upper="6.28" velocity="1.5" />
    </joint>
    <link name="link_6">
        <inertial>
            <mass value="0.4" />
            <origin rpy="0 0 0" xyz="0.0 0.0 0.0" />
            <inertia ixx="0.01042" ixy="0.001177" ixz="-0.0008871" iyy="0.01045" iyz="0.0002226" izz="0.01817" />
        </inertial>
        <visual>
            <geometry>
                <mesh filename="package://robot_slider_description/meshes/link_6.stl" scale="1 1 1" />
            </geometry>
            <material name="voilet">
                <color rgba="1.0 0.3 1.0 1.0" />
            </material>
        </visual>
        <collision>
            <geometry>
                <mesh filename="package://robot_slider_description/meshes/link_6.stl" scale="1 1 1" />
            </geometry>
        </collision>
    </link>
    <link name="base" />
    <joint name="base_link-base" type="fixed">
        <origin rpy="0 0 0" xyz="0 0 0.670" />
        <parent link="base_link" />
        <child link="base" />
    </joint>
    <link name="flange" />
    <joint name="joint_6-flange" type="fixed">
        <origin rpy="0 0 0" xyz="0 0 0" />
        <parent link="link_6" />
        <child link="flange" />
    </joint>
    <joint name="grinder_joint" type="fixed">
        <origin rpy="0 0 -1.57" xyz="0.35 0 0" />
        <parent link="flange" />
        <child link="tool" />
    </joint>
    <link name="tool">
        <inertial>
            <mass value="4" />
            <origin rpy="0 0 0" xyz="0.0 0.0 0.0" />
            <inertia ixx="0.01042" ixy="0.001177" ixz="-0.0008871" iyy="0.01045" iyz="0.0002226" izz="0.01817" />
        </inertial>
        <visual>
            <geometry>
                <mesh filename="package://robot_slider_description/meshes/Unnamed-endEffector_stependEffector.dae" scale="1.5 1.5 1.5" />
            </geometry>
            <material name="voilet">
                <color rgba="1.0 0.3 1.0 1.0" />
            </material>
        </visual>
        <collision>
            <geometry>
                <mesh filename="package://robot_slider_description/meshes/Unnamed-endEffector_stependEffector.dae" scale="1.5 1.5 1.5" />
            </geometry>
        </collision>
    </link>
    <link name="tool_face" />
    <joint name="toolface_joint" type="fixed">
        <origin rpy="1.57 0 0" xyz="0 0 0" />
        <parent link="tool" />
        <child link="tool_face" />
    </joint>
    <joint name="boat_base_slider_joint" type="fixed">
        <origin rpy="1.5707963267948966 0 0" xyz="0 -0.235 -1.5" />
        <parent link="robot_stand" />
        <child link="base_link" />
    </joint>
    <transmission name="joint_1_tran">
        <type>transmission_interface/SimpleTransmission</type>
        <joint name="joint_1">
            <hardwareInterface>hardware_interface/PositionJointInterface</hardwareInterface>
        </joint>
        <actuator name="joint_1_motor">
            <hardwareInterface>hardware_interface/PositionJointInterface</hardwareInterface>
            <mechanicalReduction>1</mechanicalReduction>
        </actuator>
    </transmission>
    <!-- Transmissions  -->
    <transmission name="joint_2_tran">
        <type>transmission_interface/SimpleTransmission</type>
        <joint name="joint_2">
            <hardwareInterface>hardware_interface/PositionJointInterface</hardwareInterface>
        </joint>
        <actuator name="joint_2_motor">
            <hardwareInterface>hardware_interface/PositionJointInterface</hardwareInterface>
            <mechanicalReduction>1</mechanicalReduction>
        </actuator>
    </transmission>
    <!-- Transmissions  -->
    <transmission name="joint_3_tran">
        <type>transmission_interface/SimpleTransmission</type>
        <joint name="joint_3">
            <hardwareInterface>hardware_interface/PositionJointInterface</hardwareInterface>
        </joint>
        <actuator name="joint_3_motor">
            <hardwareInterface>hardware_interface/PositionJointInterface</hardwareInterface>
            <mechanicalReduction>1</mechanicalReduction>
        </actuator>
    </transmission>
    <!-- Transmissions  -->
    <transmission name="joint_4_tran">
        <type>transmission_interface/SimpleTransmission</type>
        <joint name="joint_4">
            <hardwareInterface>hardware_interface/PositionJointInterface</hardwareInterface>
        </joint>
        <actuator name="joint_4_motor">
            <hardwareInterface>hardware_interface/PositionJointInterface</hardwareInterface>
            <mechanicalReduction>1</mechanicalReduction>
        </actuator>
    </transmission>
    <!-- Transmissions  -->
    <transmission name="joint_5_tran">
        <type>transmission_interface/SimpleTransmission</type>
        <joint name="joint_5">
            <hardwareInterface>hardware_interface/PositionJointInterface</hardwareInterface>
        </joint>
        <actuator name="joint_5_motor">
            <hardwareInterface>hardware_interface/PositionJointInterface</hardwareInterface>
            <mechanicalReduction>1</mechanicalReduction>
        </actuator>
    </transmission>
    <!-- Transmissions  -->
    <transmission name="joint_6_tran">
        <type>transmission_interface/SimpleTransmission</type>
        <joint name="joint_6">
            <hardwareInterface>hardware_interface/PositionJointInterface</hardwareInterface>
        </joint>
        <actuator name="joint_6_motor">
            <hardwareInterface>hardware_interface/PositionJointInterface</hardwareInterface>
            <mechanicalReduction>1</mechanicalReduction>
        </actuator>
    </transmission>
    <transmission name="prismatic_tran">
        <type>transmission_interface/SimpleTransmission</type>
        <joint name="slider_link_rail_stand_right_joint">
            <hardwareInterface>hardware_interface/PositionJointInterface</hardwareInterface>
        </joint>
        <actuator name="prismatic_motor">
            <hardwareInterface>hardware_interface/PositionJointInterface</hardwareInterface>
            <mechanicalReduction>1</mechanicalReduction>
        </actuator>
    </transmission>
    <transmission name="robot_stand_slider_tran">
        <type>transmission_interface/SimpleTransmission</type>
        <joint name="robot_stand_slider_joint">
            <hardwareInterface>hardware_interface/PositionJointInterface</hardwareInterface>
        </joint>
        <actuator name="robot_stand_slider_motor">
            <hardwareInterface>hardware_interface/PositionJointInterface</hardwareInterface>
            <mechanicalReduction>1</mechanicalReduction>
        </actuator>
    </transmission>
    <!-- Gazebo colors -->
    <gazebo reference="base_link">
        <material>Gazebo/Grey</material>
        <plugin name="gazebo_ros_control">
            <robotNamespace>/</robotNamespace>
        </plugin>
    </gazebo>
    <gazebo reference="link_1">
        <material>Gazebo/</material>
    </gazebo>
    <gazebo reference="link_2">
        <material>Gazebo/Orange</material>
    </gazebo>
    <gazebo reference="link_3">
        <material>Gazebo/</material>
    </gazebo>
    <gazebo reference="link_4">
        <material>Gazebo/Grey</material>
    </gazebo>
    <gazebo reference="link_5">
        <material>Gazebo/Orange</material>
    </gazebo>
    <gazebo reference="link_6">
        <material>Gazebo/Orange</material>
    </gazebo>
    <gazebo reference="tool">
        <material>Gazebo/Blue</material>
    </gazebo>
    <gazebo reference="boat_link">
        <material>Gazebo/Blue</material>
    </gazebo>
    <gazebo reference="rail_stand_link_right">
        <material>Gazebo/Orange</material>
    </gazebo>
    <gazebo reference="slider_link">
        <material>Gazebo/Orange</material>
    </gazebo>
    <gazebo reference="robot_stand">
        <material>Gazebo/Blue</material>
    </gazebo>
    <!-- Self collision in Gazebo -->
    <!-- Plugins and publishers -->
    <gazebo>
        <plugin filename="libgazebo_ros_control.so" name="gazebo_ros_control">
            <robotSimType>gazebo_ros_control/DefaultRobotHWSim</robotSimType>
        </plugin>
    </gazebo>
</robot>

